<?xml version="1.0"?>
<robot name="racecar" xmlns:xacro="http://www.ros.org/wiki/xacro">
<!-- Based off of:
mit-racecar/racecar_gazebo
-->

<xacro:property name="wheel_y_offset" value="0.2" />
<xacro:property name="wheel_z_offset" value="-0.1" />
<xacro:property name="rear_wheel_x_offset" value="-0.2" />
<xacro:property name="front_wheel_x_offset" value="0.4" />

<xacro:property name="pi_2" value="1.5708" />
<xacro:property name="pi_4" value="0.7854" />

<xacro:property name="chassis_geometry">
  <box size="0.5 0.3 0.2" />
</xacro:property>

<xacro:property name="wheel_geometry">
  <cylinder length="0.05" radius="0.1" />
</xacro:property>

<xacro:property name="chassis_inertia">
   <inertial>
     <origin xyz="0 0 0" rpy="0 0 0"/>
     <mass value="100"/>
     <inertia ixx="100"  ixy="0"  ixz="0" iyy="100" iyz="0" izz="10" />
   </inertial>
</xacro:property>

<xacro:property name="wheel_inertia">
   <inertial>
     <origin xyz="0 0 0" rpy="0 0 0"/>
     <mass value="1"/>
     <inertia ixx="10"  ixy="0"  ixz="0" iyy="10" iyz="0" izz="1" />
   </inertial>
</xacro:property>

<xacro:macro name="wheel_params" params="link">
    <gazebo reference="${link}">
        <mu1 value="1.0"/>
        <mu2 value="1.0"/>
        <kp  value="10000000.0" />
        <kd  value="2.0" />
        <material>Gazebo/Black</material>
    </gazebo>
</xacro:macro>

<xacro:macro name="wheel_transmission" params="name">
  <transmission name="${name}_transmission" type="SimpleTransmission">
    <type>transmission_interface/SimpleTransmission</type>
    <joint name="${name}_joint">
      <hardwareInterface>EffortJointInterface</hardwareInterface>
    </joint>
    <actuator name="${name}_motor">
      <hardwareInterface>EffortJointInterface</hardwareInterface>
      <mechanicalReduction>1</mechanicalReduction>
    </actuator>
  </transmission>
</xacro:macro>

<xacro:macro name="turn_transmission" params="name">
  <transmission name="${name}_transmission" type="SimpleTransmission">
    <type>transmission_interface/SimpleTransmission</type>
    <joint name="${name}_joint">
      <hardwareInterface>EffortJointInterface</hardwareInterface>
    </joint>
    <actuator name="${name}_motor">
      <hardwareInterface>EffortJointInterface</hardwareInterface>
      <mechanicalReduction>1</mechanicalReduction>
    </actuator>
  </transmission>
</xacro:macro>



<link name="base_link"/>

<joint name="base_joint" type="fixed">
    <origin xyz="0 0 0" rpy="0 0 0"/>
    <parent link="base_link"/>
    <child link="chassis_link"/>
</joint>

<link name="chassis_link">
    <visual>
        <origin xyz="0 0 0" rpy="0 0 0" />
        <geometry>
            <xacro:insert_block name="chassis_geometry" />
        </geometry>
            <material name="Cyan">
            <color rgba="0 1.0 1.0 1.0"/>
        </material>
   </visual>
    <xacro:insert_block name="chassis_inertia" />
   <collision>
     <origin xyz="0 0 0" rpy="0 0 0"/>
     <geometry>
       <xacro:insert_block name="chassis_geometry" />
     </geometry>
   </collision>
</link>

<joint name="left_rear_wheel_joint" type="continuous">
    <origin xyz="${rear_wheel_x_offset} ${wheel_y_offset} ${wheel_z_offset}" rpy="${pi_2} 0 0"/>
    <parent link="chassis_link"/>
    <child link="left_rear_wheel_link"/>
    <axis xyz="0 0 -1" />
    <limit effort="10" velocity="100" />
</joint>
<xacro:wheel_transmission name="left_rear_wheel" />

<link name="left_rear_wheel_link">
    <visual>
        <origin xyz="0 0 0" rpy="0 0 0" />
        <geometry>
            <xacro:insert_block name="wheel_geometry" />
        </geometry>
            <material name="Black">
            <color rgba="0 0 0 1"/>
        </material>
   </visual>
   <xacro:insert_block name="wheel_inertia" />
   <collision>
     <origin xyz="0 0 0" rpy="0 0 0"/>
     <geometry>
       <xacro:insert_block name="wheel_geometry" />
     </geometry>
   </collision>
</link>


<joint name="right_rear_wheel_joint" type="continuous">
    <origin xyz="${rear_wheel_x_offset} -${wheel_y_offset} ${wheel_z_offset}" rpy="${pi_2} 0 0"/>
    <parent link="chassis_link"/>
    <child link="right_rear_wheel_link"/>
    <axis xyz="0 0 -1" />
    <limit effort="10" velocity="100" />
</joint>
<xacro:wheel_transmission name="right_rear_wheel" />

<link name="right_rear_wheel_link">
    <visual>
        <origin xyz="0 0 0" rpy="0 0 0" />
        <geometry>
            <xacro:insert_block name="wheel_geometry" />
        </geometry>
            <material name="Black">
            <color rgba="0 0 0 1"/>
        </material>
   </visual>
   <xacro:insert_block name="wheel_inertia" />
   <collision>
     <origin xyz="0 0 0" rpy="0 0 0"/>
     <geometry>
       <xacro:insert_block name="wheel_geometry" />
     </geometry>
   </collision>
</link>



<joint name="left_front_wheel_joint" type="continuous">
    <origin xyz="${front_wheel_x_offset} ${wheel_y_offset} ${wheel_z_offset}" rpy="${pi_2} 0 0"/>
    <parent link="chassis_link"/>
    <child link="left_front_wheel_link"/>
    <axis xyz="0 0 -1" />
    <limit effort="10" velocity="100" />
</joint>
<xacro:wheel_transmission name="left_front_wheel" />

<link name="left_front_wheel_link">
    <visual>
        <origin xyz="0 0 0" rpy="0 0 0" />
        <geometry>
            <xacro:insert_block name="wheel_geometry" />
        </geometry>
        <material name="Grey">
            <color rgba="0.2 0.2 0.2 1"/>
        </material>
   </visual>
   <xacro:insert_block name="wheel_inertia" />
   <collision>
     <origin xyz="0 0 0" rpy="0 0 0"/>
     <geometry>
       <xacro:insert_block name="wheel_geometry" />
     </geometry>
   </collision>
</link>
<xacro:wheel_transmission name="right_front_wheel" />


<joint name="right_front_wheel_joint" type="continuous">
    <origin xyz="${front_wheel_x_offset} -${wheel_y_offset} ${wheel_z_offset}" rpy="${pi_2} 0 0"/>
    <parent link="chassis_link"/>
    <child link="right_front_wheel_link"/>
    <axis xyz="0 0 -1" />
    <limit effort="10" velocity="100" />
</joint>

<link name="right_front_wheel_link">
    <visual>
        <origin xyz="0 0 0" rpy="0 0 0" />
        <geometry>
            <xacro:insert_block name="wheel_geometry" />
        </geometry>
        <material name="Grey">
            <color rgba="0.2 0.2 0.2 1"/>
        </material>
   </visual>
   <xacro:insert_block name="wheel_inertia" />
   <collision>
     <origin xyz="0 0 0" rpy="0 0 0"/>
     <geometry>
       <xacro:insert_block name="wheel_geometry" />
     </geometry>
   </collision>
</link>

<gazebo>
  <plugin name="gazebo_ros_control" filename="libgazebo_ros_control.so">
    <robotNamespace>/racecar/internal</robotNamespace>
  </plugin>
</gazebo>




<xacro:wheel_params link="left_rear_wheel_link"/>
<xacro:wheel_params link="right_rear_wheel_link"/>
<xacro:wheel_params link="left_front_wheel_link"/>
<xacro:wheel_params link="right_front_wheel_link"/>


<gazebo>
  <plugin name="skid_steer_drive_controller" filename="libgazebo_ros_skid_steer_drive.so">
    <updateRate>100.0</updateRate>
    <robotNamespace>/racecar/in</robotNamespace>
    <leftFrontJoint>left_front_wheel_joint</leftFrontJoint>
    <rightFrontJoint>right_front_wheel_joint</rightFrontJoint>
    <leftRearJoint>left_rear_wheel_joint</leftRearJoint>
    <rightRearJoint>right_rear_wheel_joint</rightRearJoint>
    <wheelSeparation>0.4</wheelSeparation>
    <wheelDiameter>0.215</wheelDiameter>
    <robotBaseFrame>chassis_link</robotBaseFrame>
    <torque>1000</torque>
    <topicName>cmd_vel</topicName>
    <broadcastTF>false</broadcastTF>
  </plugin>
</gazebo>


<joint name="hoyuko_fixed_joint" type="fixed">
    <origin xyz="0 0 0.25" rpy="0 0 0"/>
    <parent link="chassis_link"/>
    <child link="hoyuko_laser_link"/>
    <axis xyz="0 0 1" />
</joint>
<link name="hoyuko_laser_link">
   <inertial>
     <origin xyz="0 0 0" rpy="0 0 0"/>
     <mass value="1"/>
     <inertia ixx="10"  ixy="0"  ixz="0" iyy="10" iyz="0" izz="1" />
   </inertial>
</link>

<xacro:unless value="$(optenv DISABLE_GAZEBO_LASER false)">
  <gazebo reference="hoyuko_laser_link">
    <material>Gazebo/Grey</material>
    <sensor type="ray" name="hokuyo_sensor">
      <pose>0 0 0.0124 0 0 0</pose>
      <visualize>false</visualize>
      <update_rate>40</update_rate>
      <ray>
        <scan>
          <horizontal>
            <samples>1081</samples>
            <resolution>1</resolution>
            <min_angle>-2.3561944902</min_angle>
            <max_angle>2.3561944902</max_angle>
          </horizontal>
        </scan>
        <range>
          <min>0.1</min>
          <max>10.0</max>
          <resolution>0.01</resolution>
        </range>
        <noise>
          <mean>0.0</mean>
          <stddev>0.01</stddev>
        </noise>
      </ray>
      <plugin name="gazebo_ros_hokuyo_controller" filename="libgazebo_ros_laser.so">
        <topicName>racecar/out/laser_scan</topicName>
        <frameName>hoyuko_laser_link</frameName>
      </plugin>
    </sensor>
  </gazebo>
</xacro:unless>

<xacro:unless value="$(optenv DISABLE_GAZEBO_CAMERA false)">
  <gazebo reference="hoyuko_laser_link">
    <sensor type="camera" name="camera">
      <update_rate>30.0</update_rate>
      <!-- math.atan(320 / 687.8065795898438) * 2 -->
      <camera name="camera">
        <horizontal_fov>0.8709216071359963</horizontal_fov>
        <image>
          <width>640</width>
          <height>480</height>
          <format>B8G8R8</format>
        </image>
        <clip>
          <near>0.02</near>
          <far>300</far>
        </clip>
        <noise>
          <type>gaussian</type>
          <mean>0.0</mean>
          <stddev>0.007</stddev>
        </noise>
      </camera>
      <plugin name="camera_controller" filename="libgazebo_ros_camera.so">
        <alwaysOn>true</alwaysOn>
        <updateRate>30.0</updateRate>
        <cameraName>/camera/zed</cameraName>
        <imageTopicName>rgb/image_rect_color</imageTopicName>
        <cameraInfoTopicName>rgb/camera_info</cameraInfoTopicName>
        <frameName>hoyuko_laser_link</frameName>
        <hackBaseline>0</hackBaseline><!-- set this to 0.12 for the second camera -->
        <distortionK1>0.0</distortionK1>
        <distortionK2>0.0</distortionK2>
        <distortionK3>0.0</distortionK3>
        <distortionT1>0.0</distortionT1>
        <distortionT2>0.0</distortionT2>
      </plugin>
    </sensor>
  </gazebo>
</xacro:unless>


</robot>