<?xml version="1.0"?>
<robot name="racecar" xmlns:xacro="http://www.ros.org/wiki/xacro">
<!-- Based off of:
mit-racecar/racecar_gazebo
-->

<xacro:property name="wheel_y_offset" value="0.2" />
<xacro:property name="wheel_z_offset" value="-0.1" />
<xacro:property name="rear_wheel_x_offset" value="-0.2" />
<xacro:property name="front_wheel_x_offset" value="0.2" />

<xacro:property name="pi_2" value="1.5708" />
<xacro:property name="pi_4" value="0.7854" />

<xacro:property name="chassis_geometry">
  <box size="0.5 0.3 0.2" />
</xacro:property>

<xacro:property name="wheel_geometry">
  <cylinder length="0.05" radius="0.1" />
</xacro:property>

<xacro:property name="wheel_inertia">
   <inertial>
     <origin xyz="0 0 0" rpy="0 0 0"/>
     <mass value="1"/>
     <inertia ixx="1"  ixy="0"  ixz="0" iyy="10" iyz="0" izz="10" />
   </inertial>
</xacro:property>

<xacro:macro name="wheel_transmission" params="name">
  <transmission name="${name}_transmission" type="SimpleTransmission">
    <type>transmission_interface/SimpleTransmission</type>
    <joint name="${name}_joint">
      <hardwareInterface>EffortJointInterface</hardwareInterface>
    </joint>
    <actuator name="${name}_motor">
      <hardwareInterface>EffortJointInterface</hardwareInterface>
      <mechanicalReduction>1</mechanicalReduction>
    </actuator>
  </transmission>
</xacro:macro>

<xacro:macro name="turn_transmission" params="name">
  <transmission name="${name}_transmission" type="SimpleTransmission">
    <type>transmission_interface/SimpleTransmission</type>
    <joint name="${name}_joint">
      <hardwareInterface>EffortJointInterface</hardwareInterface>
    </joint>
    <actuator name="${name}_motor">
      <hardwareInterface>EffortJointInterface</hardwareInterface>
      <mechanicalReduction>1</mechanicalReduction>
    </actuator>
  </transmission>
</xacro:macro>

<link name="base_link"/>

<joint name="base_joint" type="fixed">
    <origin xyz="0 0 0" rpy="0 0 0"/>
    <parent link="base_link"/>
    <child link="chassis_link"/>
</joint>

<link name="chassis_link">
    <visual>
        <origin xyz="0 0 0" rpy="0 0 0" />
        <geometry>
            <xacro:insert_block name="chassis_geometry" />
        </geometry>
            <material name="Cyan">
            <color rgba="0 1.0 1.0 1.0"/>
        </material>
   </visual>
   <inertial>
     <origin xyz="0 0 0" rpy="0 0 0"/>
     <mass value="10"/>
     <inertia ixx="100"  ixy="0"  ixz="0" iyy="100" iyz="0" izz="100" />
   </inertial>
   <collision>
     <origin xyz="0 0 0" rpy="0 0 0"/>
     <geometry>
       <xacro:insert_block name="chassis_geometry" />
     </geometry>
   </collision>
</link>

<joint name="left_rear_wheel_joint" type="continuous">
    <origin xyz="${rear_wheel_x_offset} ${wheel_y_offset} ${wheel_z_offset}" rpy="${pi_2} 0 0"/>
    <parent link="chassis_link"/>
    <child link="left_rear_wheel_link"/>
    <axis xyz="0 0 -1" />
    <limit effort="10" velocity="100" />
</joint>
<xacro:wheel_transmission name="left_rear_wheel" />

<link name="left_rear_wheel_link">
    <visual>
        <origin xyz="0 0 0" rpy="0 0 0" />
        <geometry>
            <xacro:insert_block name="wheel_geometry" />
        </geometry>
            <material name="Black">
            <color rgba="0 0 0 1"/>
        </material>
   </visual>
   <xacro:insert_block name="wheel_inertia" />
   <collision>
     <origin xyz="0 0 0" rpy="0 0 0"/>
     <geometry>
       <xacro:insert_block name="wheel_geometry" />
     </geometry>
   </collision>
</link>


<joint name="right_rear_wheel_joint" type="continuous">
    <origin xyz="${rear_wheel_x_offset} -${wheel_y_offset} ${wheel_z_offset}" rpy="-${pi_2} 0 0"/>
    <parent link="chassis_link"/>
    <child link="right_rear_wheel_link"/>
    <axis xyz="0 0 1" />
    <limit effort="10" velocity="100" />
</joint>
<xacro:wheel_transmission name="right_rear_wheel" />

<link name="right_rear_wheel_link">
    <visual>
        <origin xyz="0 0 0" rpy="0 0 0" />
        <geometry>
            <xacro:insert_block name="wheel_geometry" />
        </geometry>
            <material name="Black">
            <color rgba="0 0 0 1"/>
        </material>
   </visual>
   <xacro:insert_block name="wheel_inertia" />
   <collision>
     <origin xyz="0 0 0" rpy="0 0 0"/>
     <geometry>
       <xacro:insert_block name="wheel_geometry" />
     </geometry>
   </collision>
</link>



<joint name="left_front_wheel_turn_joint" type="revolute">
    <origin xyz="${front_wheel_x_offset} ${wheel_y_offset} ${wheel_z_offset}" rpy="0 0 0"/>
    <parent link="chassis_link"/>
    <child link="left_front_wheel_turn_link"/>
    <axis xyz="0 0 1" />
    <limit effort="10" velocity="10" lower="-${pi_4}" upper="${pi_4}" />
</joint>
<xacro:turn_transmission name="left_front_wheel_turn" />

<link name="left_front_wheel_turn_link">
   <inertial>
     <origin xyz="0 0 0" rpy="0 0 0"/>
     <mass value="0.1"/>
     <inertia ixx="0.1"  ixy="0"  ixz="0" iyy="0.1" iyz="0" izz="0.1" />
   </inertial>
</link>

<joint name="left_front_wheel_joint" type="continuous">
    <origin xyz="0 0 0" rpy="-${pi_2} 0 0"/>
    <parent link="left_front_wheel_turn_link"/>
    <child link="left_front_wheel_link"/>
    <axis xyz="0 0 1" />
    <limit effort="10" velocity="100" />
</joint>
<xacro:wheel_transmission name="left_front_wheel" />

<link name="left_front_wheel_link">
    <visual>
        <origin xyz="0 0 0" rpy="0 0 0" />
        <geometry>
            <xacro:insert_block name="wheel_geometry" />
        </geometry>
        <material name="Grey">
            <color rgba="0.2 0.2 0.2 1"/>
        </material>
   </visual>
   <xacro:insert_block name="wheel_inertia" />
   <collision>
     <origin xyz="0 0 0" rpy="0 0 0"/>
     <geometry>
       <xacro:insert_block name="wheel_geometry" />
     </geometry>
   </collision>
</link>



<joint name="right_front_wheel_turn_joint" type="revolute">
    <origin xyz="${front_wheel_x_offset} -${wheel_y_offset} ${wheel_z_offset}" rpy="0 0 0"/>
    <parent link="chassis_link"/>
    <child link="right_front_wheel_turn_link"/>
    <axis xyz="0 0 1" />
    <limit effort="10" velocity="10" lower="-${pi_4}" upper="${pi_4}" />
</joint>
<xacro:turn_transmission name="right_front_wheel_turn" />

<link name="right_front_wheel_turn_link">
   <inertial>
     <origin xyz="0 0 0" rpy="0 0 0"/>
     <mass value="0.1"/>
     <inertia ixx="0.1"  ixy="0"  ixz="0" iyy="0.1" iyz="0" izz="0.1" />
   </inertial>
</link>

<joint name="right_front_wheel_joint" type="continuous">
    <origin xyz="0 0 0" rpy="-${pi_2} 0 0"/>
    <parent link="right_front_wheel_turn_link"/>
    <child link="right_front_wheel_link"/>
    <axis xyz="0 0 1" />
    <limit effort="10" velocity="100" />
</joint>
<xacro:wheel_transmission name="right_front_wheel" />

<link name="right_front_wheel_link">
    <visual>
        <origin xyz="0 0 0" rpy="0 0 0" />
        <geometry>
            <xacro:insert_block name="wheel_geometry" />
        </geometry>
        <material name="Grey">
            <color rgba="0.2 0.2 0.2 1"/>
        </material>
   </visual>
   <xacro:insert_block name="wheel_inertia" />
   <collision>
     <origin xyz="0 0 0" rpy="0 0 0"/>
     <geometry>
       <xacro:insert_block name="wheel_geometry" />
     </geometry>
   </collision>
</link>

<gazebo>
  <plugin name="gazebo_ros_control" filename="libgazebo_ros_control.so">
    <robotNamespace>/racecar/internal</robotNamespace>
  </plugin>
</gazebo>



<gazebo reference="chassis_link">
  <mu1 value="0.0"/>
  <mu2 value="0.0"/>
  <kp  value="10000000.0" />
  <kd  value="1.0" />
  <material>Gazebo/Blue</material>
</gazebo>

<gazebo reference="left_rear_wheel_link">
  <mu1 value="100.0"/>
  <mu2 value="50.0"/>
  <kp  value="10000000.0" />
  <kd  value="1.0" />
  <fdir1 value="1 0 0"/>
  <material>Gazebo/Black</material>
</gazebo>

<gazebo reference="right_rear_wheel_link">
  <mu1 value="100.0"/>
  <mu2 value="50.0"/>
  <kp  value="10000000.0" />
  <kd  value="1.0" />
  <fdir1 value="1 0 0"/>
  <material>Gazebo/Black</material>
</gazebo>

<gazebo reference="left_front_wheel_link">
  <mu1 value="100.0"/>
  <mu2 value="50.0"/>
  <kp  value="10000000.0" />
  <kd  value="1.0" />
  <fdir1 value="0 0 1"/>
  <material>Gazebo/Black</material>
</gazebo>

<gazebo reference="right_front_wheel_link">
  <mu1 value="100.0"/>
  <mu2 value="50.0"/>
  <kp  value="10000000.0" />
  <kd  value="1.0" />
  <fdir1 value="0 0 1"/>
  <material>Gazebo/Black</material>
</gazebo>

<gazebo>
  <plugin name="skid_steer_drive_controller" filename="libgazebo_ros_skid_steer_drive.so">
    <updateRate>100.0</updateRate>
    <robotNamespace>/racecar/in</robotNamespace>
    <leftFrontJoint>left_front_wheel_joint</leftFrontJoint>
    <rightFrontJoint>right_front_wheel_joint</rightFrontJoint>
    <leftRearJoint>left_rear_wheel_joint</leftRearJoint>
    <rightRearJoint>right_rear_wheel_joint</rightRearJoint>
    <wheelSeparation>0.4</wheelSeparation>
    <wheelDiameter>0.215</wheelDiameter>
    <robotBaseFrame>chassis_link</robotBaseFrame>
    <torque>20</torque>
    <topicName>cmd_vel</topicName>
    <broadcastTF>false</broadcastTF>
  </plugin>
</gazebo>


</robot>